Workbook

Sheet SKILL
A2: Aura, Spell, AoE, Fire Level: (1-20) Reservation: 50% Mana Cooldown Time: 1.20 sec Can Store 1 Use(s) Cast Time: Instant Requires Level 24 Casts an aura that adds fire damage to the attacks and spells of you and your allies. +(0-1.9) metres to radius You and nearby allies deal (16-109) to (23-155) additional Fire Damage with Attacks You and nearby allies deal (16-109) to (23-155) additional Fire Damage with Spells | B2: Earthquake Attack, AoE, Melee, Duration, Slam Level: (1-20) Cost: (10-13) Mana Attack Speed: 75% of base Attack Damage: (143-229)% of base Effectiveness of Added Damage: (143-229)% AoE Radius: 18 / 28 Requires Level 28 Smashes the ground, dealing damage in an area and cracking the earth. The crack will erupt in a powerful aftershock after a duration. Cracks created before the first one has erupted will not generate their own aftershocks. Requires an Axe, Mace, Sceptre, Staff or Unarmed. Base duration is 1.00 second Aftershock deals 150% more Damage with Hits and Ailments | C2: Exsanguinate Spell, Chaining, Physical, Duration Level: (1-20) Cost: (16-46) Life Cast Time: 0.80 sec Critical Strike Chance: 6.00% Effectiveness of Added Damage: (150-270)% Requires Level 12 Releases several tendrils of blood from your character, targeting enemies in a narrow angle in front of you. The beams deal physical damage and inflict a physical damage over time debuff to enemies, which can stack up to 3 times. Effects which allow skills to chain can apply to these tendrils. Deals (17-1193) to (25-1789) Physical Damage Deals (26.9-1534.2) Base Physical Damage per second Base duration is 1.00 second Modifiers to Spell Damage apply to this Skill's Damage Over Time effect Fires tendrils at up to (7-9) Targets | D2: Ground Slam Attack, AoE, Melee, Slam Level: (1-20) Cost: (6-11) Mana Attack Speed: 90% of base Attack Damage: (132-356)% of base Effectiveness of Added Damage: (132-356)% AoE Radius: 35 Slams the ground in front of you, creating a wave that travels forward and damages enemies with an increased chance to stun. The wave deals more damage to closer enemies. Requires an Axe, Mace, Sceptre, Staff or Unarmed. 25% reduced Enemy Stun Threshold +(0-1) metre to radius Deals up to (40-49)% more Damage with Hits to closer targets | E2: Herald of Ash Spell, AoE, Fire, Herald, Duration Level: (1-20) Reservation: 25% Mana Cooldown Time: 1.00 sec Can Store 1 Use(s) Cast Time: Instant AoE Radius: 10 Requires Level 16 Grants a buff providing fire damage based on your physical damage. While you have this buff, if you kill an enemy, other enemies near them will be burned based on the overkill damage. The burn inflicted by this skill can only be affected by modifiers to damage over time (burning damage is damage over time). Base duration is 4.00 seconds Base Burning Damage is 25% of Overkill Damage (0-38)% more Burning Damage Buff grants (15-20)% of your Physical Damage as Extra Fire Damage | F2: Molten Strike Attack, Projectile, AoE, Melee, Strike, Fire Level: (1-20) Cost: (6-10) Mana Attack Damage: (126-329)% of base Effectiveness of Added Damage: (126-329)% Projectile Speed: 750 Infuses your melee weapon with molten energies to attack with physical and fire damage. This attack causes balls of molten magma to launch forth from the enemies you hit, divided amongst all enemies hit by the strike. These will deal area attack damage to enemies where they land. Fires 4 Projectiles 60% of Physical Damage Converted to Fire Damage Projectiles deal 60% less Damage with Hits and Ailments | G2: Pride Spell, AoE, Aura, Physical Level: (1-20) Reservation: 50% Mana Cooldown Time: 1.20 sec Can Store 1 Use(s) Cast Time: Instant Requires Level 24 Casts an aura that causes nearby enemies to take more physical damage. +(0-1) metre to radius Nearby Enemies take at least (15-19)% more Physical Damage, raising up to (30-39)% as they stay in the Aura for 4 seconds | H2: Reap Spell, Physical, AoE, Duration Level: (1-20) Cost: (25-46) Life Cast Time: 0.80 sec Critical Strike Chance: 6.00% Effectiveness of Added Damage: (150-210)% Requires Level 28 A bloody scythe swipes across a selected area, applying a physical damage over time debuff and hitting enemies with physical damage. If any survive, you gain a blood charge which raises the damage and cost of the skill. Players can have 5 maximum blood charges. Deals (57-943) to (86-1414) Physical Damage Deals (138.2-2002.5) Base Physical Damage per second Base duration is 1.00 second Modifiers to Spell Damage apply to this Skill's Damage Over Time effect Gain a Blood Charge if this Skill Hits Enemies and none of them Die Lose a Blood Charge when an Enemy Dies while affected by this Skill's Debuff Costs 20% more Life per Blood Charge Deals 15% more Damage per Blood Charge | I2: Smite Lightning, Melee, Attack, AoE, Duration, Strike, Aura Level: (1-20) Cost: (7-12) Mana Attack Speed: 85% of base Attack Damage: (225-488)% of base Effectiveness of Added Damage: (225-488)% Performs a melee attack, and causes lightning to strike a nearby enemy, dealing damage in an area. Each target can only be hit once by this skill. Hitting an enemy grants an aura for a duration. Requires a Sword, Axe, Mace, Sceptre, Staff or Unarmed. 50% of Physical Damage Converted to Lightning Damage Base duration is 4.00 seconds (30-20)% less Area Damage Base radius is (1.5-2.1) metres Base Aura radius is (3.6-4.2) metres Lightning strikes 1 target within 5 metres Aura grants (1-12) to (4-220) added Lightning Damage Aura grants (10-19)% chance to Shock | J2: Summon Stone Golem Minion, Spell, Golem, Physical Level: (1-20) Cost: (30-54) Mana Cooldown Time: 6.00 sec Can Store 1 Use(s) Cast Time: 1.00 sec Requires Level 34 Summons a Stone Golem that grants you life regeneration and defences. In addition to its melee attack, the Stone Golem uses a rolling charge and a powerful slam that can taunt enemies. Maximum 1 Summoned Golem Golems grant (33-105) Life Regenerated per second Golems grant 20% increased Defences | K2: Swordstorm Attack, Melee, AoE, Retaliation Level: (1-20) Cost: (7-10) Mana Cooldown Time: 3.00 sec Can Store 1 Use(s) Attack Damage: (123-247)% of base Effectiveness of Added Damage: (123-247)% Requires Level 16 Retaliate against a blocked hit with a hail of blades that rains down in front of you, repeatedly dealing the damage of both your weapons combined. Requires Dual Wielding Melee Weapons. Cannot be used by default Becomes Usable once for 2 seconds when you Block a Hit Can't be Evaded Base radius is (1.8-2.3) metres Damages Enemies 8 times | L2: Volcanic Fissure Melee, Attack, Projectile, AoE, Slam, Fire Level: (1-20) Cost: (8-13) Mana Attack Speed: 80% of base Attack Damage: (177-344)% of base Effectiveness of Added Damage: (177-344)% Requires Level 12 Slam the ground, creating a winding fissure that deals area damage while travelling outwards. When it reaches the target location it erupts, releasing a burst of molten projectiles. Requires an Axe, Mace, Sceptre, Staff or Unarmed. Fires 5 Projectiles 60% of Physical Damage Converted to Fire Damage Projectiles deal 50% less Damage with Hits and Ailments
A4: Animate Weapon Duration, Minion, Spell, Physical Level: (1-20) Cost: (4-16) Mana Cast Time: 0.60 sec Requires Level 4 Animates a Melee Weapon Item or Lingering Blade to fight by your side. You cannot animate unidentified Weapons. Will not animate weapons with 6 sockets. Cannot be used by Traps or Mines. Base duration is 40.00 seconds Maximum (5-14) Animated Weapons Can use Items requiring up to Level (9-100) Minions' Attacks deal (5-126) to (8-184) additional Physical Damage Animated Lingering Blades deal (1-17) to (2-80) Added Attack Physical Damage Minions deal (0-38)% more Damage Minions have (0-38)% more Attack Speed | B4: Barrage Attack, Projectile, Bow Level: (1-20) Cost: (5-9) Mana Attack Speed: 115% of base Attack Damage: (47-54)% of base Effectiveness of Added Damage: (47-55)% Requires Level 12 After a short preparation time, you fire individual projectiles repeatedly with a Bow or Wand. These projectiles have a small randomised spread. This skill cannot be Triggered. Fires 5 Projectiles Fires Projectiles sequentially | C4: Blade Vortex Spell, AoE, Duration, Physical Level: (1-20) Cost: (6-16) Mana Cast Time: 0.50 sec Critical Strike Chance: 6.00% Effectiveness of Added Damage: 30% Requires Level 12 This spell creates ethereal blades which orbit in an area around you, dealing damage every 0.6 seconds to all enemies in their radius. As more blades are added, the damage becomes greater and more frequent. Deals (3-140) to (5-211) Physical Damage Base duration is 4.00 seconds +(0-0.2) metres to radius 35% increased Hit Rate for each blade 35% more Damage for each blade Can have up to 10 active spinning blades | D4: Blast Rain Fire, Attack, AoE, Projectile, Bow Level: (1-20) Cost: (7-10) Mana Attack Damage: (30-35)% of base Effectiveness of Added Damage: (30-36)% Requires Level 28 Fires arrows up in the air, to rain down in an area. Each arrow deals area damage around where it lands, and they will all overlap on the targeted location. Fires 6 Arrows 100% of Physical Damage Converted to Fire Damage Penetrates (20-30)% Fire Resistance | E4: Burning Arrow Attack, Projectile, Fire, Bow Level: (1-20) Cost: (8-14) Mana Attack Speed: 70% of base Attack Damage: (280-420)% of base Effectiveness of Added Damage: (280-420)% Projectile Speed: 3260 Fires a burning arrow that deals fire damage and has a chance to ignite. 25% chance to Ignite enemies 100% of Physical Damage Converted to Fire Damage | F4: Cobra Lash Attack, Projectile, Chaos Level: (1-20) Cost: (5-8) Mana Attack Speed: 120% of base Attack Damage: (125-205)% of base Effectiveness of Added Damage: (125-205)% Fires a poisonous projectile based on your weapon that will chain between enemies. Requires a Dagger or Claw. 8% more Damage with Hits and Ailments for each remaining Chain Chains +(3-5) Times 60% of Physical Damage Converted to Chaos Damage 40% chance to Poison on Hit | G4: Cyclone Attack, AoE, Melee, Movement, Channelling Level: (1-20) Cost: (2-3) Mana Attack Speed: 300% of base Attack Damage: (81-150)% of base Effectiveness of Added Damage: (81-150)% AoE Radius: 1.6 Requires Level 28 Channel this skill to move towards a targeted location while spinning constantly attacking enemies in an area around you. While channelling this skill, you cannot be knocked back. 15% increased Area of Effect per 0.1 metre additional Melee Strike Range (30-20)% less Movement Speed | H4: Detonate Dead Spell, AoE, Fire Level: (1-20) Cost: (5-20) Mana Cast Time: 0.60 sec Critical Strike Chance: 6.00% Effectiveness of Added Damage: 160% AoE Radius: 22 Requires Level 4 Targets a corpse, and deals spell damage to enemies around the corpse, as well as causing the corpse to explode, dealing fire damage. The explosion is not affected by modifiers to spell damage and cannot be reflected. Deals (15-798) to (22-1197) Fire Damage Explosion deals base Fire Damage equal to (6-7.9)% of the corpse's Maximum Life Base radius is (2.2-2.6) metres | I4: Explosive Arrow Attack, Projectile, AoE, Duration, Fire, Bow Level: (1-20) Cost: (7-10) Mana Projectile Speed: 3260 AoE Radius: 15 Requires Level 28 Fires an arrow which will stick into an enemy or wall, and then explode, dealing area damage around it, either after a duration or when the maximum number of arrows stuck to that target is reached. If an enemy has multiple Explosive Arrows stuck in them, the first one to explode will consume the others, adding their damage to its explosion. Base duration is 1.00 second Explosion deals 50% less Base Damage Explosion will have (47-522) to (71-783) added Fire Damage +0.2 metres to Explosion Radius per Explosive Arrow on Target, up to a maximum of +1.2 metres Explosion deals 6% more Damage with Hits per Explosive Arrow on Target Explosion deals 3% more Damage with Ailments per Explosive Arrow on Target Maximum 20 Explosive Arrows stuck in an Enemy | J4: Explosive Concoction Attack, AoE, Fire, Cold, Lightning, Projectile Level: (1-20) Cost: (6-9) Mana Attack Speed: 115% of base Requires Level 28 Throws a bottle that explodes to deal unarmed attack damage in an area. Can consume charges from your Ruby, Sapphire, and Topaz flasks to add further damage. Requires an empty main hand, and no off-hand weapon. (65-806) to (98-1210) Added Fire Damage +6% to Critical Strike Chance Base radius is 1.8 metres Can consume Charges from Ruby, Sapphire, and Topaz Flasks Consumes 1 Charge per Projectile Fired from 1 Flask of each valid type, if possible Deals (57-706) to (86-1058) Added Cold Damage if Charges were consumed from a Sapphire Flask Deals (12-151) to (143-1764) Added Lightning Damage if Charges were consumed from a Topaz Flask +(120-196)% to Damage over Time Multiplier with Ignite if Charges were consumed from a Ruby Flask | K4: Flicker Strike Attack, Melee, Strike, Movement, Duration Level: (1-20) Cost: (5-8) Mana Cooldown Time: 2.00 sec Can Store 1 Use(s) Attack Speed: 120% of base Attack Damage: (177-408)% of base Effectiveness of Added Damage: (177-408)% Requires Level 10 Teleports the character to a nearby monster and attacks with a melee weapon. If no specific monster is targeted, one is picked at random. Grants a buff that increases movement speed for a duration. The cooldown can be bypassed by expending a Frenzy Charge. Base duration is 3.00 seconds 10% increased Attack Speed per Frenzy Charge 15% chance to gain a Frenzy Charge on Hit Buff grants 20% increased Movement Speed | L4: Frost Blades Attack, Projectile, Melee, Strike, Cold Level: (1-20) Cost: (6-10) Mana Attack Damage: (143-409)% of base Effectiveness of Added Damage: (143-409)% Projectile Speed: 2250 Attack enemies with increased range, releasing icy blades from the first enemy hit which fly at other enemies. Requires a Melee Weapon. Fires (5-8) Projectiles 60% of Physical Damage Converted to Cold Damage +(1.8-2.1) metres to Melee Strike Range Projectiles deal 30% less Damage with Hits and Ailments | M4: Galvanic Arrow Lightning, Attack, Projectile, AoE, Bow Level: (1-20) Cost: (6-10) Mana Attack Damage: (92-113)% of base Effectiveness of Added Damage: (92-113)% Fire a trio of electrical arrows that quickly dissipate, vanishing shortly after being loosed. The arrows are fired with such force that they create a burst of lightning, damaging enemies in a cone in front of you. 50% of Physical Damage Converted to Lightning Damage Fires 3 Arrows +(0-0.5) metres to radius Increases and Reductions to Projectile Speed also apply to this Skill's Area of Effect | N4: Haste Aura, Spell, AoE Level: (1-20) Reservation: 50% Mana Cooldown Time: 1.20 sec Can Store 1 Use(s) Cast Time: Instant AoE Radius: 36 Requires Level 24 Casts an aura that increases the movement speed, attack speed and cast speed of you and your allies. +(0-1.9) metres to radius You and nearby allies gain (10-16)% increased Movement Speed You and nearby allies gain (15-24)% increased Attack Speed You and nearby allies gain (15-24)% increased Cast Speed | O4: Hatred Aura, Spell, AoE, Cold Level: (1-20) Reservation: 50% Mana Cooldown Time: 1.20 sec Can Store 1 Use(s) Cast Time: Instant AoE Radius: 36 Requires Level 24 Casts an aura that grants extra cold damage based on physical damage to you and your allies. +(0-1.9) metres to radius You and nearby allies gain (30-39)% of Physical Damage as Extra Cold Damage | P4: Herald of Agony Spell, Herald, Minion, Chaos, Physical Level: (1-20) Reservation: 25% Mana Cooldown Time: 1.00 sec Can Store 1 Use(s) Cast Time: Instant Requires Level 16 Grants a buff giving more poison damage and a chance to inflict poison. When you poison an enemy while you have this buff, you gain Virulence, and summon an Agony Crawler minion that uses projectile and area attacks. You will lose Virulence over time, at a rate which increases the more Virulence you have. The minion will die when you have no Virulence. Maximum 1 Summoned Agony Crawler Buff grants 20% chance to Poison on Hit Grants Virulence when you Poison an Enemy Buff grants 10% more Damage with Poison 40 Maximum Virulence Minions cannot Taunt Enemies Agony Crawler has (2-4)% increased Attack Speed per Virulence you have Agony Crawler deals (5-9)% increased Physical Damage per Virulence you have Agony Crawler has (1-45) to (3-84) Added Physical Damage per Virulence you have | Q4: Herald of Ice Spell, AoE, Cold, Herald Level: (1-20) Reservation: 25% Mana Cooldown Time: 1.00 sec Can Store 1 Use(s) Cast Time: Instant Effectiveness of Added Damage: 80% Requires Level 16 Grants a buff adding cold damage to spells and attacks. If you shatter an enemy, this skill will cause them to explode and deal AoE cold damage to enemies near them. This damage is not affected by modifiers to spell damage. Deals (18-308) to (26-462) Cold Damage Damage cannot be Reflected Base radius is 1.2 metres Buff grants (4-38) to (5-56) Added Attack Cold Damage Buff grants (4-38) to (5-56) Added Spell Cold Damag | R4: Ice Shot Attack, Projectile, AoE, Cold, Bow Level: (1-20) Cost: (6-10) Mana Attack Damage: (149-200)% of base Effectiveness of Added Damage: (149-200)% Projectile Speed: 3260 AoE Radius: 23 / 10 Fires an arrow that converts some physical damage to cold on its target and converts all physical damage to cold in a cone behind that target. 60% of Physical Damage Converted to Cold Damage Base radius is 2.4 metres Chills Enemies as though dealing (100-195)% more Damage | S4: Lacerate Attack, AoE, Melee, Physical Level: (1-20) Cost: (10-17) Mana Attack Speed: 60% of base Attack Damage: (171-393)% of base Effectiveness of Added Damage: (171-393)% AoE Radius: 38 Requires Level 12 Slashes twice, releasing waves of force that damage enemies they hit. Enemies in the middle of the slashes can be hit by both. The slashes will have a chance to inflict bleeding in Blood Stance, or have a wider angle in Sand Stance. Can be used with Axes and Swords. You are in Blood Stance by default. +(0-0.9) metres to radius (50-88)% more Damage with Bleeding while in Blood Stance 25% chance to cause Bleeding while in Blood Stance 50% increased angle while in Sand Stance | T4: Lightning Arrow Attack, AoE, Projectile, Lightning, Bow Level: (1-20) Cost: (6-10) Mana Attack Damage: (149-177)% of base Effectiveness of Added Damage: (149-177)% Projectile Speed: 3260 Requires Level 12 Fires a charged arrow which damages enemies by causing them to be struck by a bolt of lightning, which also damages a number of surrounding enemies. 50% of Physical Damage Converted to Lightning Damage Hits up to 3 additional enemies near the target Shocks Enemies as though dealing (100-290)% more Damage | U4: Lightning Strike Attack, Projectile, Melee, Strike, Lightning Level: (1-20) Cost: (6-10) Mana Attack Damage: (198-456)% of base Effectiveness of Added Damage: (198-456)% Requires Level 12 Infuses your melee weapon with electrical energies as you swing. In addition to converting some of your physical damage to lightning damage, the stored energy is released from the weapon as projectiles as you strike, flying out to hit farther-away enemies. The projectiles cannot miss if the melee attack hit a target. 50% of Physical Damage Converted to Lightning Damage Fires 3 Projectiles Projectiles deal 50% less Damage with Hits and Ailments | V4: Poisonous Concoction Attack, AoE, Chaos, Projectile Level: (1-20) Cost: (5-9) Mana Attack Speed: 115% of base Requires Level 12 Throws a bottle that explodes to deal unarmed attack damage in an area and has a chance to poison. Can consume charges from a Life flask to add further damage. Requires an empty main hand, and no off-hand weapon. (22-537) to (33-806) Added Chaos Damage 40% chance to Poison on Hit +6% to Critical Strike Chance Base radius is 1.8 metres Consumes 1 Charge per Projectile Fired from 1 Life Flask, if possible Added Chaos Damage equal to (4-16)% of Flask's Recovery Amount if Charges were consumed from a Life Flask | W4: Precision Aura, Critical, Spell, AoE Level: (1-20) Reservation: (22-186) Mana Cooldown Time: 1.20 sec Can Store 1 Use(s) Cast Time: Instant Requires Level 10 Casts an aura that grants accuracy and critical strike chance to you and your allies. +(0-1.9) metres to radius You and nearby allies gain (20-58)% increased Critical Strike Chance You and nearby allies gain +(93-701) to Accuracy Rating | X4: Rain of Arrows Attack, AoE, Projectile, Bow Level: (1-20) Cost: (6-10) Mana Attack Damage: (48-60)% of base Effectiveness of Added Damage: (48-60)% AoE Radius: 24 Requires Level 12 Fires multiple arrows into the air, to land in sequence after a delay, starting at the targeted location and spreading outwards in all directions. Each arrow deals damage in an area around it. Half of the arrows will land directly on targets if there are targets in their range. Fires (18-22) Arrows | Y4: Scourge Arrow Attack, Projectile, Channelling, Chaos, Bow Level: (1-20) Cost: (4-5) Mana Attack Speed: 190% of base Attack Damage: (48-65)% of base Effectiveness of Added Damage: (48-65)% Requires Level 28 Channel to infuse an arrow with chaos, gaining stages while it is held. Release to fire it, leaving spore pods in its wake. Each spore pod blooms, firing thorn arrows, which travel for a short time before dissipating. Modifiers that cause additional projectiles to be fired will only apply to the initial arrows, and the spore pods will be divided between those arrows. Arrows Pierce all Targets 60% of Physical Damage Converted to Chaos Damage 150% more Damage with Hits and Ailments per Stage Maximum 5 Stages Leaves 1 Spore Pod per Stage Each Spore Pod fires 9 Thorn Arrows Thorn Arrows deal (60-50)% less Damage | Z4: Tornado Shot Attack, Projectile, Bow Level: (1-20) Cost: (9-13) Mana Attack Speed: 80% of base Attack Damage: (100-120)% of base Effectiveness of Added Damage: (100-120)% Requires Level 28 Fires a piercing shot that travels until it reaches the targeted location. It will then fire projectiles out in all directions from that point, which will travel for a short time before disappearing. Fires 3 secondary Projectiles | AA4: Toxic Rain Attack, AoE, Chaos, Duration, Projectile, Bow Level: (1-20) Cost: (6-10) Mana Attack Damage: (50-72)% of base Effectiveness of Added Damage: (50-73)% Requires Level 12 Fire arrows into the air that rain down around the targeted area, dealing damage to enemies they hit and creating spore pods where they land. Each spore pod deals chaos damage over time to nearby enemies and slows their movement speed. The pods last for a duration before bursting, dealing area damage. Deals (8-238) Base Chaos Damage per second Base duration is 1.00 second Fires 5 Arrows Modifiers to Projectile Damage apply to this Skill's Damage Over Time effect 60% of Physical Damage Converted to Chaos Damage Each Spore Pod applies 5% less Movement Speed to nearby Enemies, to a maximum of 30%
A6: Arc Spell, Chaining, Lightning Level: (1-20) Cost: (8-23) Mana Cast Time: 0.70 sec Critical Strike Chance: 6.00% Effectiveness of Added Damage: 120% Requires Level 12 An arc of lightning reaches from the caster to a targeted enemy and chains to other enemies, but not immediately back. Each time the arc chains, it will also chain a secondary arc to another enemy that the main arc has not already hit, which cannot chain further. Deals (6-198) to (32-1122) Lightning Damage Chains +(4-7) Times 15% more Damage with Hits and Ailments for each remaining Chain | B6: Ball Lightning Spell, Projectile, AoE, Lightning Level: (1-20) Cost: (12-23) Mana Cast Time: 0.70 sec Critical Strike Chance: 5.00% Effectiveness of Added Damage: 60% Projectile Speed: 400 AoE Radius: 22 Requires Level 28 Fires a slow-moving projectile that damages each enemy in an area around it repeatedly with bolts of lightning. Deals (2-32) to (47-617) Lightning Damage Base radius is 1.8 metres | C6: Blight Spell, Chaos, AoE, Channelling, Duration Level: (1-20) Cost: (2-5) Mana Cast Time: 0.30 sec AoE Radius: 26 Apply a debuff to enemies in front of you which deals chaos damage over time. Enemies who aren't already debuffed by Blight are also hindered for a shorter secondary duration, slowing their movement. Continued channelling adds layers of damage to the debuff, each with their own duration. Deals (5.9-421.5) Base Chaos Damage per second Base duration is 2.00 seconds Base secondary duration is 1.00 seconds Modifiers to Spell Damage apply to this Skill's Damage Over Time effect +(0-0.6) metres to radius 80% reduced Movement Speed Debuff can have up to 20 layers of Damage | D6: Blazing Salvo Spell, AoE, Fire, Projectile Level: (1-20) Cost: (8-23) Mana Cast Time: 0.70 sec Critical Strike Chance: 6.00% Effectiveness of Added Damage: 60% Requires Level 12 Fires projectiles which fly in an arc, dealing area damage on impact with either enemies or the ground near where you target. Targeting farther away causes the projectiles to spread out and land over a wider area. Deals (7-270) to (10-405) Fire Damage Fires (5-7) Projectiles | E6: Eye of Winter Spell, Projectile, Cold Level: (1-20) Cost: (14-26) Mana Cast Time: 0.80 sec Critical Strike Chance: 6.00% Effectiveness of Added Damage: 55% Requires Level 28 Fires a single eye projectile which constantly releases shard projectiles in a spiral. The shards will damage enemies they impact, dealing cold damage. The eye cannot damage enemies. When the eye dissipates or collides with terrain, it releases a faster spiral of extra shards. Deals (16-245) to (25-367) Cold Damage Modifiers to number of Projectiles only apply to the final Spiral Fires 8 Shard Projectiles in a Spiral when Projectile ends Projectiles continuously gain Damage, up to 200% more Damage by the time they dissipate | F6: Fireball Projectile, Spell, AoE, Fire Level: (1-20) Cost: (6-25) Mana Cast Time: 0.75 sec Critical Strike Chance: 6.00% Effectiveness of Added Damage: (260-370)% Projectile Speed: 1040 AoE Radius: 9 Unleashes a ball of fire towards a target which explodes, damaging nearby foes. Deals (9-1640) to (14-2460) Fire Damage 25% chance to Ignite enemies Base radius is (0.9-1.4) metres | G6: Forbidden Rite Spell, AoE, Chaos, Projectile Level: (1-20) Cost: (8-21) Mana Cast Time: 0.75 sec Critical Strike Chance: 6.00% Effectiveness of Added Damage: 110% Requires Level 16 Lobs an exploding projectile near the targeted location, and extra projectiles toward enemies around you. The projectiles deal chaos damage based on your life and energy shield. Casting this spell damages you. Deals (15-498) to (22-747) Chaos Damage Deals 5% of your maximum Energy Shield as base Chaos Damage Deals 12% of your maximum Life as base Chaos Damage Take 40% of maximum Life and 25% of maximum Energy Shield as Chaos Damage Fires extra Projectiles at up to (6-7) surrounding Enemies | H6: Freezing Pulse Spell, Projectile, Cold Level: (1-20) Cost: (5-21) Mana Cast Time: 0.65 sec Critical Strike Chance: 6.00% Effectiveness of Added Damage: (250-330)% Projectile Speed: 1800 An icy projectile which has a chance to freeze enemies it passes through. The projectile fades quickly, reducing damage and freezing chance until it dissipates. Deals (8-1458) to (12-2188) Cold Damage Projectiles Pierce all Targets Projectiles continuously lose Damage, up to 50% less Damage by the time they dissipate Projectiles have 25% chance to Freeze, which is lost over the first quarter of their flight | I6: Herald of Thunder Spell, AoE, Duration, Lightning, Herald Level: (1-20) Reservation: 25% Mana Cooldown Time: 1.00 sec Can Store 1 Use(s) Cast Time: Instant AoE Radius: 32 Requires Level 16 Grants a buff which adds lightning damage to spells and attacks. If you kill a shocked enemy, this skill will create a storm, causing lightning bolts to strike enemies around you for a duration. The damage inflicted by this skill is not affected by modifiers to spell damage. Deals (1-23) to (31-1108) Lightning Damage Cannot inflict Shock Base duration is 6.00 seconds Storm Hits an Enemy every 0.25 Seconds Creates a storm when you Kill a Shocked Enemy Buff grants (2-19) to (7-76) Added Attack Lightning Damage Buff grants (2-19) to (7-76) Added Spell Lightning Damage | J6: Kinetic Blast Attack, Projectile, AoE Level: (1-20) Cost: (6-9) Mana Attack Speed: 115% of base Attack Damage: (140-155)% of base Effectiveness of Added Damage: (140-155)% AoE Radius: 14 Requires Level 28 Fires a projectile from a Wand that causes a series of area explosions in a secondary radius around its point of impact, each damaging enemies. Kinetic Blast creates 4 additional explosions Increases and Reductions to Spell Damage also apply to Attack Damage from this Skill at 200% of their value 35% less Area Damage Base explosion radius is 1.4 metres Base secondary radius is 2 metres | K6: Kinetic Rain Attack, AoE, Projectile, Duration, Trigger Level: (1-20) Cost: (7-10) Mana Attack Damage: (20-25)% of base Effectiveness of Added Damage: (20-25)% Requires Level 28 Swing your wand to cause a number of projectiles to rain down within a large area in front of you, directly targeting the locations of enemies in the area. The locations where each projectile will land are shown with markers before they fall. Each projectile explodes when hitting the ground, dealing area damage and triggering Kinetic Anomaly. Cannot be used by Totems, Traps, or Mines. Increases and Reductions to Spell Damage also apply to Attack Damage from this Skill at 150% of their value Fires 8 Projectiles Base targeting area length is 9 metres Base targeting area width is 4.5 metres Base explosion radius is 1.2 metres Increases and Reductions to Spell Damage also apply to Attack Damage from this Skill at 150% of their value Base duration is 6.00 seconds Base explosion radius is 1.2 metres Maximum 30 Anomalies This Skill is Triggered when Projectiles from Kinetic Rain explode | L6: Orb of Storms Lightning, Spell, AoE, Chaining, Orb Level: (1-20) Cost: (22-16) Mana Cooldown Time: 0.50 sec Can Store 1 Use(s) Cast Time: 0.50 sec Critical Strike Chance: 5.00% Effectiveness of Added Damage: (80-110)% Requires Level 4 Creates a stationary electrical orb that strikes enemies in its area of effect with beams of lightning that can then split to hit more enemies. Modifiers to cast speed will increase how frequently it does this. Casting this skill again will replace the previous orb. Deals (3-304) to (8-913) Lightning Damage Strikes every (3.50-2.55) seconds, and when you use a Lightning Skill near the Orb Strikes every 0.50 seconds while Channelling a Lightning Skill near the Orb Base radius is 2.8 metres Beams Split towards targets within a base radius of 3.5 metres Beam Splits towards 3 additional targets Orb disappears after (10-29) Strikes | M6: Raise Zombie Spell, Minion Level: (1-20) Cost: (9-28) Mana Cast Time: 0.85 sec Raises a zombie minion from a corpse, which will follow you and attack enemies with a melee strike. Maximum (3-6) Raised Zombies Minions have (0-38)% more Maximum Life | N6: Righteous Fire Spell, AoE, Fire Level: (1-20) Cooldown Time: 0.30 sec Can Store 1 Use(s) Cast Time: Instant Requires Level 16 Engulfs you in magical fire that rapidly burns you and nearby enemies. Your spell damage is substantially increased while under this effect. The effect ends when you have 1 life remaining. Deals 70% of your Maximum Life as Base Fire Damage per second Deals 70% of your Maximum Energy Shield as Base Fire Damage per second You Burn for 90% of your Maximum Life per second as Fire Damage You Burn for 70% of your Maximum Energy Shield per second as Fire Damage Grants (20-39)% more Spell Damage Base radius is (1.8-2.3) metres | O6: Summon Carrion Golem Physical, Minion, Spell, Golem Level: (1-20) Cost: (30-54) Mana Cooldown Time: 6.00 sec Can Store 1 Use(s) Cast Time: 1.00 sec Requires Level 34 Summons a Carrion Golem that grants added physical damage for your non-golem minions. The Carrion Golem attacks with a series of slashes that increase in speed and damage, as well as a cascade of bone spikes, and deals more damage for each of your non-golem minions near it. Maximum 1 Summoned Golem Golems deal 5% more Damage per Non-Golem Minion near them, up to 50% Golems grant (7-27) to (11-41) additional Physical Damage for Non-Golem Minions | P6: Vortex Spell, AoE, Cold, Duration, Nova Level: (1-20) Cost: (13-25) Mana Cast Time: 0.75 sec Critical Strike Chance: 6.00% Effectiveness of Added Damage: (130-210)% AoE Radius: 2 Requires Level 28 An icy blast explodes around the caster, dealing cold damage to enemies, and leaving behind a whirling vortex which deals cold damage over time and chills enemies caught in it. Deals (48-933) to (72-1399) Cold Damage Base duration is 3.00 seconds Deals (115.6-2772.8) Base Cold Damage per second Modifiers to Spell Damage apply to this Skill's Damage Over Time effect Base radius is 2 metres Base secondary radius is 2 metres

Sheet SUPPORT
A1: Added Fire Damage Support Fire, Physical, Support Icon: F Level: (1-20) Cost & Reservation Multiplier: 120% Requires Level 8 Supports any skill that hits enemies. Supported Skills gain (25-39)% of Physical Damage as Extra Fire Damage | B1: Brutality Support Physical, Support Icon: U Level: (1-20) Cost & Reservation Multiplier: 140% Requires Level 38 Supports any skill that deals damage. Supported Skills deal (25-39)% more Physical Damage Supported Skills deal no Chaos Damage Supported Skills deal no Elemental Damage | C1: Burning Damage Support Fire, Support Icon: b Level: (1-20) Cost & Reservation Multiplier: 130% Requires Level 31 Supports any skill that hits enemies, or can deal burning damage directly. Supported Skills deal (20-34)% more Burning Damage | D1: Chance to Bleed Support Attack, Physical, Support Icon: E Level: (1-20) Cost & Reservation Multiplier: 120% Supports attack skills. Supported Attacks have 25% chance to cause Bleeding Supported Attacks deal (10-29)% more Damage with Bleeding | E1: Cold to Fire Support Cold, Fire, Support Icon: x Level: (1-20) Cost & Reservation Multiplier: 120% Requires Level 18 Supports any skill that hits enemies. Supported Skills gain (10-29)% of Cold Damage as Extra Fire Damage Supported Skills have 50% of Cold Damage Converted to Fire Damage | F1: Cruelty Support Support, Duration Icon: Y Level: (1-20) Cost & Reservation Multiplier: 140% Requires Level 18 Supports any skill that hits enemies. Minions cannot gain Cruelty. Supported Skills deal (15-24)% more Damage with Hits Cruelty has a Base Duration of 4 seconds Hits from Supported Skills grant Cruelty (0-19)% increased Effect of Cruelty granted by Supported Skills | G1: lemental Damage with Attacks Support Attack, Support Icon: W Level: (1-20) Cost & Reservation Multiplier: 130% Requires Level 18 Supports attack skills. Supported Attack Skills deal (20-34)% more Elemental Damage | H1: Endurance Charge on Melee Stun Support Support, Melee, Attack Icon: e Level: (1-20) Cost & Reservation Multiplier: 120% Requires Level 18 Supports melee attack skills. 4% more Damage per Endurance Charge Supported Skills have (0-19)% reduced Enemy Stun Threshold Gain an Endurance Charge when you Stun an Enemy with a Melee Hit from Supported Skills | I1: Fire Penetration Support Fire, Support Icon: V Level: (1-20) Cost & Reservation Multiplier: 130% Requires Level 31 Supports any skill that hits enemies, making those hits penetrate enemy fire resistance. Supported Skills Penetrate (20-34)% Fire Resistance | J1: Less Duration Support Support, Duration Icon: d Level: (1-20) Cost & Reservation Multiplier: 130% Requires Level 31 Supports any skill that has a duration. Supported Skills deal (10-19)% more Damage Supported Skills have (40-49)% less Skill Effect Duration | K1: Maim Support Attack, Physical, Support Icon: m Level: (1-20) Cost & Reservation Multiplier: 130% Requires Level 8 Supports attack skills, or other skills that can maim enemies. Supported Skills deal (10-19)% more Physical Damage Supported Attacks have 30% chance to Maim on Hit Enemies Maimed by Supported Skills take 10% increased Physical Damage | L1: Melee Physical Damage Support Melee, Physical, Support, Attack Icon: M Level: (1-20) Cost & Reservation Multiplier: 130% Requires Level 18 Supports melee attack skills. Supported Skills deal (30-49)% more Melee Physical Damage Supported Skills deal (30-49)% more Damage with Bleeding and Poison caused by Melee Hits Supported Skills have 10% less Attack Speed | M1: More Duration Support Support, Duration Icon: D Level: (1-20) Cost & Reservation Multiplier: 130% Requires Level 31 Supports any skill with a duration. Supported Skills have (30-39)% more Skill Effect Duration | N1: Multistrike Support Attack, Melee, Support Icon: 3 Level: (1-20) Cost & Reservation Multiplier: 150% Requires Level 38 Supports melee attack skills, making them repeat twice when used, targeting a random enemy each time. Cannot support Vaal skills, channelling skills, travel skills, retaliation skills or triggered skills. Supported Skills Repeat 2 additional times Supported Skills have (35-44)% more Melee Attack Speed Supported Skills deal (30-20)% less Attack Damage First Repeat of Supported Skills deals 22% more Damage Second Repeat of Supported Skills deals 44% more Damage | O1: Pulverise Support AoE, Support, Melee, Attack Icon: P Level: (1-20) Cost & Reservation Multiplier: 130% Requires Level 31 Supports melee attack skills. Supported Skills have (25-34)% increased Area of Effect Supported Skills have 15% less Attack Speed Supported Skills deal (35-49)% more Melee Area Damage | P1: Ruthless Support Slam, Support, Melee, Attack, Strike Icon: u Level: (1-20) Cost & Reservation Multiplier: 120% Supports melee strike or slam skills. Every third time you use a supported attack, that use of the skill will be more powerful. Every third Attack with Supported Melee Attacks deals a Ruthless Blow Ruthless Blows with Supported Skills deal (70-98)% more Melee Damage Ruthless Blows with Supported Skills deal (70-98)% more Damage with Ailments caused by Melee Hits Ruthless Blows with Supported Skills have a base Stun Duration of 0.8 seconds | Q1: Shockwave Support Support, Melee, Attack, AoE Icon: s Level: (1-20) Cost & Reservation Multiplier: 140% Cooldown Time: 1.00 sec Can Store (1-4) Use(s) Requires Level 18 Supports melee attack skills. Cannot support triggered attacks, attacks used by things other than you, or skills which create minions. Supported Skills will Trigger Shockwave on Melee Hit Supported Skills can only be used with Maces, Sceptres or Staves Base radius is (2.4-2.7) metres (0-38)% increased Cooldown Recovery Rate | R1: Stun Support Support Icon: t Level: (1-20) Requires Level 8 Supports any skill that hits enemies, making it easier to stun enemies with those skills. Supported Skills have (30-49)% reduced Enemy Stun Threshold
A3: Added Cold Damage Support Cold, Support Icon: C Level: (1-20) Cost & Reservation Multiplier: 120% Requires Level 8 Supports any skill that hits enemies. Supported Skills have (4-152) to (6-228) added Cold Damag | B3: Additional Accuracy Support Attack, Support Icon: a Level: (1-20) Cost & Reservation Multiplier: 110% Requires Level 8 Supports attack skills. Supported Skills have +(74-1034) to Accuracy Rating | C3: Barrage Support Bow, Attack, Support, Projectile Icon: N Level: (1-20) Cost & Reservation Multiplier: 150% Requires Level 38 Supports projectile attack skills that use bows or wands. Cannot support triggered skills, channelled skills, or skills that create Minions. Supported Skills deal (68-62)% less Damage Supported Skills Fire Projectiles sequentially Supported Skills fire 3 additional Projectiles Supported Skills have 5% more Attack Time per Projectile Supported Skills have 5% more Trap and Mine Throwing Time per Projectile Supported Skills can only be used with Bows or Wands | D3: Chain Support Support, Chaining, Projectile Icon: c Level: (1-20) Cost & Reservation Multiplier: 140% Requires Level 38 Supports projectile skills, and any other skills that chain. Supported Skills Chain +2 times Supported Skills deal (30-11)% less Damage with Hits | E3: Chance to Poison Support Chaos, Support Icon: O Level: (1-20) Cost & Reservation Multiplier: 120% Supports any skill that hits enemies. Supported Skills have 40% chance to Poison on Hit Supported Skills have (1-94) to (2-141) added Chaos Damage | F3: Cold Penetration Support Cold, Support Icon: V Level: (1-20) Cost & Reservation Multiplier: 130% Requires Level 31 Supports any skill that hits enemies, making those hits penetrate enemy cold resistance. Supported Skills Penetrate (20-34)% Cold Resistance | G3: Critical Strike Affliction Support Critical, Support Icon: o Level: (1-20) Cost & Reservation Multiplier: 130% Requires Level 31 Supports any skill that hits enemies. Supported Skills have +(70-98)% Damage over Time Multiplier for Ailments from Critical Strikes | H3: Culling Strike Support Support Icon: X Level: (1-20) Cost & Reservation Multiplier: 110% Requires Level 18 Supports any skill that hits enemies. If enemies are left below 10% of maximum life after being hit by these skills, they will be killed. Kill Enemies that have 10% Life or lower when Hit by Supported Skills Supported Skills deal (0-38)% increased Damage | I3: Deadly Ailments Support Support Icon: i Level: (1-20) Cost & Reservation Multiplier: 140% Requires Level 18 Supports any skill that hits enemies. Supported Skills deal (30-44)% more Damage with Ailments Supported Skills deal 80% less Damage with Hits | J3: Faster Attacks Support Attack, Support Icon: A Level: (1-20) Cost & Reservation Multiplier: 110% Requires Level 8 Supports attack skills. Supported Skills have (20-44)% increased Attack Speed | K3: Faster Projectiles Support Support, Projectile Icon: j Level: (1-20) Cost & Reservation Multiplier: 120% Requires Level 31 Supports projectile skills. Supported Skills have (50-69)% increased Projectile Speed Supported Skills deal (20-29)% increased Projectile Damage | L3: Fork Support Support, Projectile Icon: Y Level: (1-20) Cost & Reservation Multiplier: 130% Requires Level 31 Supports projectile skills, making their projectiles fork into two projectiles the first time they hit an enemy and don't pierce it. Projectiles from Supported Skills Fork Supported Skills deal (-10-9)% more Projectile Damage | M3: Greater Multiple Projectiles Support Support, Projectile Icon: P Level: (1-20) Cost & Reservation Multiplier: 150% Requires Level 38 Supports projectile skills. Supported Skills deal (35-26)% less Projectile Damage Supported Skills fire 4 additional Projectiles | N3: Greater Volley Support Support, Projectile Icon: ≣ Level: (1-20) Cost & Reservation Multiplier: 150% Requires Level 38 Supports skills that fire projectiles from the user. Does not affect projectiles fired from other locations as secondary effects. Does not support skills that fire projectiles in a spiral. Supported Skills fire 4 additional Projectiles Supported Skills also fire Projectiles from up to 4 points on each side of you Supported Skills deal (30-21)% less Projectile Damage | O3: Hypothermia Support Cold, Support Icon: D Level: (1-20) Cost & Reservation Multiplier: 130% Requires Level 31 Supports any skill that deals damage. Supported Skills have +20% chance to Freeze Enemies which are Chilled Supported Skills deal (20-29)% more Cold Damage Over Time Supported Skills deal (20-29)% more Damage with Hits and Ailments against Chilled Enemies | P3: Impale Support Attack, Physical, Support Icon: I Level: (1-20) Cost & Reservation Multiplier: 130% Requires Level 31 Supports attack skills. Supported Attacks have 60% chance to Impale Enemies on Hit Supported Attacks have (0-28)% increased Impale Effect | Q3: Mirage Archer Support Bow, Attack, Support, Duration Icon: M Level: (1-20) Cost & Reservation Multiplier: 130% Requires Level 4 Supports attack skills that can be used with bows. Supported skills can only be used with bows. Cannot support Vaal skills, minion skills, movement skills, or skills used by totems, traps, or mines. Maximum 1 Summoned Mirage Archer When you Hit an Enemy with an Arrow from a Supported Skill, Summon a Mirage Archer which uses that Skill Mirage Archer can use Triggered Attacks as though they were not Triggered Mirage Archer uses Supported Skill with 60% less Attack Speed Mirage Archer lasts 4 seconds Mirage Archer deals (40-31)% less Damage with Supported Skills | R3: Multiple Projectiles Support Support, Projectile Icon: l Level: (1-20) Cost & Reservation Multiplier: 130% Requires Level 8 Supports projectile skills. Supported Skills deal (15-6)% less Projectile Damage Supported Skills fire 2 additional Projectiles | S3: Pierce Support Support, Projectile Icon: p Level: (1-20) Cost & Reservation Multiplier: 120% Requires Level 4 Supports projectile skills. Projectiles from Supported Skills Pierce (2-4) additional Targets Supported Skills deal (0-19)% more Projectile Damage | T3: Returning Projectiles Support Support, Projectile Icon: R Level: (1-20) Cost & Reservation Multiplier: 150% Requires Level 38 Supports projectile skills. Projectiles from Supported Skills Return to you Projectiles from Supported Skills deal (70-66)% less Damage with Hits and Ailments while Returning Projectiles from Supported Skills Pierce all Targets while Returning | U3: Slower Projectiles Support Support, Projectile Icon: J Level: (1-20) Cost & Reservation Multiplier: 120% Requires Level 31 Supports projectile skills. Supported Skills have (20-30)% less Projectile Speed Supported Skills deal (10-19)% more Projectile Damage | V3: Swift Affliction Support Support, Duration Icon: r Level: (1-20) Cost & Reservation Multiplier: 140% Requires Level 31 Supports any skill that has a duration, or can hit enemies to inflict ailments on them. Supported Skills deal (25-39)% more Damage over Time 25% less Duration of Supported Skills and Damaging Ailments they inflict | W3: Vicious Projectiles Support Projectile, Attack, Physical, Chaos, Support Icon: d Level: (1-20) Cost & Reservation Multiplier: 130% Requires Level 18 Supports projectile attack skills. Supported Skills deal (30-49)% more Chaos Damage over Time Supported Skills deal (30-49)% more Physical Damage over Time Supported Skills deal (30-49)% more Physical Projectile Attack Damage Supported Skills have 10% less Projectile Attack Speed | X3: Vile Toxins Support Support Icon: e Level: (1-20) Cost & Reservation Multiplier: 130% Requires Level 38 Supports any skill that hits enemies. Supported Skills deal 5% more Damage with Hits for each Poison on the Enemy, up to (5-8) Supported Skills deal (10-19)% more Damage with Poison | Y3: Void Manipulation Support Chaos, Support Icon: v Level: (1-20) Cost & Reservation Multiplier: 130% Requires Level 8 Supports any skill that deals damage. Supported Skills deal (20-34)% more Chaos Damage Supported Skills deal no Elemental Damage | Z3: Volley Support Support, Projectile Icon: = Level: (1-20) Cost & Reservation Multiplier: 130% Requires Level 4 Supports skills that fire projectiles from the user. Does not affect projectiles fired from other locations as secondary effects. Does not support skills that fire projectiles in a spiral. Supported Skills fire 2 additional Projectiles Supported Skills also fire Projectiles from up to 2 points on each side of you Supported Skills deal (12-3)% less Projectile Damage
D5: Added Chaos Damage Support Chaos, Support Icon: H Level: (1-20) Cost & Reservation Multiplier: 120% Requires Level 31 Supports any skill that hits enemies. Supported Skills have (18-154) to (26-231) added Chaos Damage | E5: Added Lightning Damage Support Lightning, Support Icon: L Level: (1-20) Cost & Reservation Multiplier: 120% Requires Level 8 Supports any skill that hits enemies. Supported Skills have (1-19) to (8-358) added Lightning Damage | F5: Bonechill Support Cold, Support Icon: B Level: (1-20) Cost & Reservation Multiplier: 130% Requires Level 38 Supports any skill that can chill enemies or create chilling areas. (25-44)% increased Effect of Chill inflicted with Supported Skills Enemies Chilled by Supported Skills increase Cold Damage taken by Chill Effect Enemies in Chilling Areas from Supported Skills increase Cold Damage taken by Chill Effect Supported Skills deal (5-14)% more Cold Damage | G5: Combustion Support Fire, Support Icon: i Level: (1-20) Cost & Reservation Multiplier: 130% Requires Level 8 Supports any skill that hits enemies. Supported Skills deal (10-19)% more Fire Damage Supported Skills have 25% chance to Ignite Enemies Ignited by Supported Skills have -10% to Fire Resistance | H5: Concentrated Effect Support Support, AoE Icon: o Level: (1-20) Cost & Reservation Multiplier: 140% Requires Level 18 Supports any skill with an area of effect, regardless of whether that skill deals damage. Supported Skills deal (25-39)% more Area Damage Supported Skills have 30% less Area of Effect | I5: Controlled Destruction Support Spell, Critical, Support Icon: C Level: (1-20) Cost & Reservation Multiplier: 140% Requires Level 18 Supports attack skills, or spell skills that deal damage. Supported Skills have 80% less Critical Strike Chance Supported Skills deal (25-39)% more Spell Damage | J5: Efficacy Support Support, Duration Icon: a Level: (1-20) Cost & Reservation Multiplier: 130% Requires Level 8 Supports any skill that deals damage or has a duration. Supported Skills deal (15-24)% more Damage over Time Supported Skills have (15-24)% increased Skill Effect Duration | K5: Elemental Focus Support Support Icon: F Level: (1-20) Cost & Reservation Multiplier: 130% Requires Level 18 Supports any skill that hits or burns enemies, or inflicts elemental ailments. Supported Skills deal (20-34)% more Elemental Damage Supported Skills cannot inflict Elemental Ailments | L5: Elemental Proliferation Support Cold, Fire, Lightning, Support, AoE Icon: S Level: (1-20) Cost & Reservation Multiplier: 110% Supports any skill that hits enemies, or could otherwise apply elemental ailments. (0-19)% increased Duration of Elemental Ailments on Enemies Elemental Ailments inflicted by Supported Skills spread to other enemies within (1.2-1.5) metres Supported Skills have 20% chance to Freeze, Shock and Ignite | M5: Faster Casting Support Support, Spell Icon: f Level: (1-20) Cost & Reservation Multiplier: 110% Requires Level 18 Supports non-instant spell skills. Supported Skills have (20-39)% increased Cast Speed | N5: Ignite Proliferation Support Fire, Support, AoE Icon: I Level: (1-20) Cost & Reservation Multiplier: 130% Requires Level 38 Supports any skill that hits enemies. Ignites caused by Supported Skills spread to other Enemies within (1.4-2) metres Supported Skills deal (15-24)% more Damage with Ignite | O5: Increased Area of Effect Support Support, AoE Icon: E Level: (1-20) Cost & Reservation Multiplier: 130% Requires Level 38 Supports any skill with an area of effect. Supported Skills have (30-49)% increased Area of Effect | P5: Increased Critical Damage Support Critical, Support Icon: c Level: (1-20) Cost & Reservation Multiplier: 130% Requires Level 18 Supports any skill that hits enemies. Supported Skills have +(100-138)% to Critical Strike Multiplier | Q5: Increased Critical Strikes Support Critical, Support Icon: s Level: (1-20) Cost & Reservation Multiplier: 120% Requires Level 8 Supports any skill that hits enemies. Supported Skills have (60-117)% increased Critical Strike Chance Supported Skills have +2% to Critical Strike Chance | R5: Infused Channelling Support Support, Channelling Icon: b Level: (1-20) Cost & Reservation Multiplier: 130% Requires Level 4 Supports any channelling skill, protecting you from damage while you channel it. Cannot modify the skills of minions. Supported Skills deal (20-29)% more Damage While Channelling a Supported Skill, take 12% less Damage from Hits | S5: Lightning Penetration Support Lightning, Support Icon: V Level: (1-20) Cost & Reservation Multiplier: 130% Requires Level 31 Supports any skill that hits enemies, making those hits penetrate enemy lightning resistance. Supported Skills Penetrate (20-34)% Lightning Resistance | T5: Minion Damage Support Support, Minion Icon: d Level: (1-20) Cost & Reservation Multiplier: 140% Requires Level 8 Supports skills which create Minions. Minions from Supported Skills deal (25-39)% more Damage Minions from Supported Skills have 25% less Maximum Life | U5: Minion Speed Support Movement, Support, Minion Icon: e Level: (1-20) Cost & Reservation Multiplier: 120% Requires Level 18 Supports skills which create Minions. Supported Skills have (25-34)% increased Minion Attack Speed Supported Skills have (25-34)% increased Minion Cast Speed Supported Skills have (25-44)% increased Minion Movement Speed | V5: Physical to Lightning Support Lightning, Physical, Support Icon: x Level: (1-20) Cost & Reservation Multiplier: 120% Requires Level 18 Supports any skill that hits enemies. Supported Skills gain (10-29)% of Physical Damage as Extra Lightning Damage Supported Skills have 50% of Physical Damage Converted to Lightning Damage | W5: Spell Cascade Support AoE, Spell, Support Icon: p Level: (1-20) Cost & Reservation Multiplier: 130% Requires Level 4 Supports spell skills that apply an effect to an area around a targeted location. Cannot support Vaal skills or skills used by totems, traps, or mines. Cannot modify the skills of minions. Supported Skills have (25-16)% less Area of Effect Supported Skills deal (40-31)% less Damage Supported Area of Effect Skills also affect areas in front of and behind the targeted area | X5: Spell Echo Support Spell, Support Icon: k Level: (1-20) Cost & Reservation Multiplier: 140% Requires Level 38 Supports spell skills, making them repeat when cast. Cannot support Vaal skills, totem skills, channelling skills, triggered skills, instant skills, retaliation skills, blink skills, or skills with a reservation. Supported Skills Repeat an additional time Supported Skills have (40-54)% more Cast Speed | Y5: Trinity Support Support Icon: y Level: (1-20) Cost & Reservation Multiplier: 140% Requires Level 18 Supports skills that hit enemies, causing them to gain bonuses while you have resonance of all three elements, and to grant resonance of elements other than the highest one in a hit. There is a maximum of 50 Resonance for each Element. Cannot support triggered skills, instant skills, orb skills, brands, skills with a reservation, or skills used by totems, traps, or mines. Cannot modify the skills of minions. Hits with Supported Skills for which the highest Damage Type is Elemental cause you to gain 25 Resonance of other Elements per second for 2 seconds Lose 5 Resonance per second of each Element you are not gaining Supported Skills deal 3% more Elemental Damage per 5 of lowest Resonance Supported Skills penetrate (7-16)% Elemental Resistances while each Resonance is at least 25 | Z5: Unleash Support Spell, Support Icon: q Level: (1-20) Cost & Reservation Multiplier: 140% Requires Level 38 Supports spell skills, making their effect reoccur when cast. Cannot support skills with cooldowns, triggered skills, Brand skills, Vaal skills, channelling skills, skills with a reservation, or skills used by totems, traps, or mines. Cannot modify the skills of minions. Supported Spells gain a Seal every (0.90-0.71) seconds, to a maximum of 3 Seals Supported Spells are Unsealed when cast, and their effects Reoccur for each Seal lost Supported Skills deal (45-36)% less Damage when Reoccurring

Sheet PARSED_ACTIVE
A1: SourceSheet | B1: SourceCell | C1: GemType | D1: Name | E1: Tags | F1: DamageType | G1: Scaling | H1: MechanicTags | I1: CombatRole | J1: AilmentKeywords | K1: Level | L1: Cost | M1: Reservation | N1: CostReservationMultiplier | O1: CooldownTime | P1: CanStoreUses | Q1: CastTime | R1: RequiresLevel | S1: AttackSpeed | T1: AttackDamage | U1: EffectivenessAddedDamage | V1: AoERadius | W1: ProjectileSpeed | X1: Icon | Y1: Description | Z1: ModifierLines | AA1: RawText
A2: SKILL | B2: A2 | C2: Active | D2: Anger | E2: Aura, Spell, AoE, Fire | F2: Fire | G2: Spell | H2: Aura, AoE | I2: Buff/Aura, Area | K2: (1-20) | M2: 50% Mana | O2: 1.20 sec | P2: 1 Use(s) | Q2: Instant | R2: 24 | Y2: Casts an aura that adds fire damage to the attacks and spells of you and your allies. | Z2: +(0-1.9) metres to radius You and nearby allies deal (16-109) to (23-155) additional Fire Damage with Attacks You and nearby allies deal (16-109) to (23-155) additional Fire Damage with Spells | AA2: Aura, Spell, AoE, Fire Level: (1-20) Reservation: 50% Mana Cooldown Time: 1.20 sec Can Store 1 Use(s) Cast Time: Instant Requires Level 24 Casts an aura that adds fire damage to the attacks and spells of you and your allies. +(0-1.9) metres to radius You and nearby allies deal (16-109) to (23-155) additional Fire Damage with Attacks You and nearby allies deal (16-109) to (23-155) additional Fire Damage with Spells
A3: SKILL | B3: B2 | C3: Active | D3: Earthquake | E3: Attack, AoE, Melee, Duration, Slam | G3: Attack, Melee | H3: AoE, Melee, Slam | I3: Area, Duration/DoT | J3: Shock | K3: (1-20) | L3: (10-13) Mana | R3: 28 | S3: 75% of base | T3: (143-229)% of base | U3: (143-229)% | V3: 18 / 28 | Y3: Smashes the ground, dealing damage in an area and cracking the earth. The crack will erupt in a powerful aftershock after a duration. Cracks created before the first one has erupted will not generate their own aftershocks. Requires an Axe, Mace, Sceptre, Staff or Unarmed. | Z3: Base duration is 1.00 second Aftershock deals 150% more Damage with Hits and Ailments | AA3: Earthquake Attack, AoE, Melee, Duration, Slam Level: (1-20) Cost: (10-13) Mana Attack Speed: 75% of base Attack Damage: (143-229)% of base Effectiveness of Added Damage: (143-229)% AoE Radius: 18 / 28 Requires Level 28 Smashes the ground, dealing damage in an area and cracking the earth. The crack will erupt in a powerful aftershock after a duration. Cracks created before the first one has erupted will not generate their own aftershocks. Requires an Axe, Mace, Sceptre, Staff or Unarmed. Base duration is 1.00 second Aftershock deals 150% more Damage with Hits and Ailments
A4: SKILL | B4: C2 | C4: Active | D4: Exsanguinate | E4: Spell, Chaining, Physical, Duration | F4: Physical | G4: Spell | H4: Chaining | I4: Duration/DoT, Chain | K4: (1-20) | L4: (16-46) Life | Q4: 0.80 sec | R4: 12 | U4: (150-270)% | Y4: Critical Strike Chance: 6.00% Releases several tendrils of blood from your character, targeting enemies in a narrow angle in front of you. The beams deal physical damage and inflict a physical damage over time debuff to enemies, which can stack up to 3 times. Effects which allow skills to chain can apply to these tendrils. | Z4: Deals (17-1193) to (25-1789) Physical Damage Deals (26.9-1534.2) Base Physical Damage per second Base duration is 1.00 second Modifiers to Spell Damage apply to this Skill's Damage Over Time effect Fires tendrils at up to (7-9) Targets | AA4: Exsanguinate Spell, Chaining, Physical, Duration Level: (1-20) Cost: (16-46) Life Cast Time: 0.80 sec Critical Strike Chance: 6.00% Effectiveness of Added Damage: (150-270)% Requires Level 12 Releases several tendrils of blood from your character, targeting enemies in a narrow angle in front of you. The beams deal physical damage and inflict a physical damage over time debuff to enemies, which can stack up to 3 times. Effects which allow skills to chain can apply to these tendrils. Deals (17-1193) to (25-1789) Physical Damage Deals (26.9-1534.2) Base Physical Damage per second Base duration is 1.00 second Modifiers to Spell Damage apply to this Skill's Damage Over Time effect Fires tendrils at up to (7-9) Targets
